Using TensorFlow backend.
WARNING:tensorflow:From /c1/apps/anaconda/4.3.1/lib/python3.5/site-packages/tensorflow/contrib/learn/python/learn/datasets/base.py:198: retry (from tensorflow.contrib.learn.python.learn.datasets.base) is deprecated and will be removed in a future version.
Instructions for updating:
Use the retry module or similar alternatives.
train_model imported
load_model imported
get_rank_info imported
predict_cosine_similarity imported
Word2Vec imported
WordNetLemmatizer imported
get_similar_words imported
nltk imported
prepare_data imported
sent_tokenize imported
stopwords imported
word_tokenize imported
EXP_ID                      16
N_EPOCH                    400
PATIENCE                   100
IS_TRAIN                     1
LOSS_FUNC     cosine_proximity
CP                 -0.00349464
MSE                  0.0557148
OUTPUT_DIM                 200
INPUT_DIM                  200
TIME_STEPS                   1
MODEL_ID               LSTM_15
IS_RUN                       1
RANK_SCORE                 NaN
QUIT_LOSS                  NaN
QUIT_MSE                   NaN
QUIT_EPOCH                 NaN
Name: 13, dtype: object
Traceback (most recent call last):
  File "./main.py", line 151, in <module>
    exp = start_exp(exp)
  File "./main.py", line 51, in start_exp
    import_local_package(os.path.join(CWDIR,'./experiments/models/{}.py'.format(MODEL_ID)),[])
  File "./main.py", line 20, in import_local_package
    spec.loader.exec_module(myModule)
  File "<frozen importlib._bootstrap_external>", line 661, in exec_module
  File "<frozen importlib._bootstrap_external>", line 766, in get_code
  File "<frozen importlib._bootstrap_external>", line 818, in get_data
FileNotFoundError: [Errno 2] No such file or directory: '/home/straynwang/Job_matches/./experiments/models/LSTM_15.py'
