Using TensorFlow backend.
WARNING:tensorflow:From /c1/apps/anaconda/4.3.1/lib/python3.5/site-packages/tensorflow/contrib/learn/python/learn/datasets/base.py:198: retry (from tensorflow.contrib.learn.python.learn.datasets.base) is deprecated and will be removed in a future version.
Instructions for updating:
Use the retry module or similar alternatives.
WARNING:tensorflow:From /c1/apps/anaconda/4.3.1/lib/python3.5/site-packages/keras/backend/tensorflow_backend.py:1150: calling reduce_sum (from tensorflow.python.ops.math_ops) with keep_dims is deprecated and will be removed in a future version.
Instructions for updating:
keep_dims is deprecated, use keepdims instead
WARNING:tensorflow:From /c1/apps/anaconda/4.3.1/lib/python3.5/site-packages/keras/backend/tensorflow_backend.py:1114: calling reduce_max (from tensorflow.python.ops.math_ops) with keep_dims is deprecated and will be removed in a future version.
Instructions for updating:
keep_dims is deprecated, use keepdims instead
/c1/apps/anaconda/4.3.1/lib/python3.5/site-packages/keras/engine/topology.py:1231: UserWarning: The `Merge` layer is deprecated and will be removed after 08/2017. Use instead layers from `keras.layers.merge`, e.g. `add`, `concatenate`, etc.
  return cls(**config)
WARNING:tensorflow:From /c1/apps/anaconda/4.3.1/lib/python3.5/site-packages/keras/backend/tensorflow_backend.py:2852: calling l2_normalize (from tensorflow.python.ops.nn_impl) with dim is deprecated and will be removed in a future version.
Instructions for updating:
dim is deprecated, use axis instead
WARNING:tensorflow:From /c1/apps/anaconda/4.3.1/lib/python3.5/site-packages/keras/backend/tensorflow_backend.py:1257: calling reduce_mean (from tensorflow.python.ops.math_ops) with keep_dims is deprecated and will be removed in a future version.
Instructions for updating:
keep_dims is deprecated, use keepdims instead
WARNING:tensorflow:Variable *= will be deprecated. Use variable.assign_mul if you want assignment to the variable value or 'x = x * y' if you want a new python Tensor object.
Traceback (most recent call last):
  File "./main.py", line 150, in <module>
    exp = start_exp(exp)
  File "./main.py", line 122, in start_exp
    df_log = pd.read_csv(path_training_log)
  File "/c1/apps/anaconda/4.3.1/lib/python3.5/site-packages/pandas/io/parsers.py", line 646, in parser_f
    return _read(filepath_or_buffer, kwds)
  File "/c1/apps/anaconda/4.3.1/lib/python3.5/site-packages/pandas/io/parsers.py", line 401, in _read
    data = parser.read()
  File "/c1/apps/anaconda/4.3.1/lib/python3.5/site-packages/pandas/io/parsers.py", line 939, in read
    ret = self._engine.read(nrows)
  File "/c1/apps/anaconda/4.3.1/lib/python3.5/site-packages/pandas/io/parsers.py", line 1508, in read
    data = self._reader.read(nrows)
  File "pandas/parser.pyx", line 848, in pandas.parser.TextReader.read (pandas/parser.c:10415)
  File "pandas/parser.pyx", line 870, in pandas.parser.TextReader._read_low_memory (pandas/parser.c:10691)
  File "pandas/parser.pyx", line 924, in pandas.parser.TextReader._read_rows (pandas/parser.c:11437)
  File "pandas/parser.pyx", line 911, in pandas.parser.TextReader._tokenize_rows (pandas/parser.c:11308)
  File "pandas/parser.pyx", line 2024, in pandas.parser.raise_parser_error (pandas/parser.c:27037)
pandas.io.common.CParserError: Error tokenizing data. C error: Expected 5 fields in line 10, saw 9

